Workbook

Sheet Petunjuk
B2: Template Praktikum STRIDE + DREAD
B3: Mata kuliah Cybersecurity · Pertemuan 3 Threat Modelling · Dosen: Muhamad Yusril Helmi Setyawan
B5: MULAI DARI SINI
B6: Tujuan | C6: Anda akan mencari ancaman keamanan pada SATU aplikasi, mengelompokkannya dengan STRIDE, menilai seberapa bahayanya dengan DREAD, lalu mengurutkan mana yang harus diperbaiki lebih dulu.
B7: Ide dasarnya | C7: Tiga pertanyaan: (1) Apa yang perlu dilindungi? (2) Siapa atau apa yang bisa merusaknya, lewat jalan mana? (3) Seberapa parah dan seberapa mudah? STRIDE menjawab 'ini jenis ancaman apa'. DREAD menjawab 'seberapa parah ancaman ini'.
B8: Hasil yang dikumpulkan | C8: File Excel ini yang sudah terisi: sheet Profil_Aplikasi (lengkap) dan MINIMAL 6 ancaman pada sheet STRIDE_DREAD_Template (disarankan 8–10), masing-masing dengan alasan skor, bukti, dan saran perbaikan.
B9: Perkiraan waktu | C9: 3–4 jam. Kerjakan BERURUTAN dari Langkah 1. Jangan menilai DREAD sebelum ancaman dan STRIDE selesai.
B10: Istilah asing? | C10: Buka sheet Glosarium_Istilah (69 istilah dengan bahasa sederhana). Contoh lengkap cara berpikir ada di sheet Contoh_Pengisian.
B12: ALUR KERJA — IKUTI LANGKAH DEMI LANGKAH
B13: Langkah 1 Baca dulu (±20 menit) | C13: • Baca sheet Petunjuk ini sampai habis. • Buka sheet Contoh_Pengisian: ada 3 ancaman lengkap pada aplikasi fiktif, dengan penjelasan cara berpikirnya. • Lihat sekilas STRIDE_Guidelines dan DREAD_Guidelines. Belum perlu hafal; Anda akan kembali ke sana saat mengisi.
B14: Langkah 2 Pilih aplikasi dan isi ringkasannya | C14: • Pilih SATU aplikasi yang kode atau cara kerjanya bisa Anda lihat: proyek web milik sendiri, tugas mata kuliah lain, atau aplikasi latihan resmi (mis. OWASP Juice Shop, DVWA). Atau pakai aplikasi yang ditentukan dosen. • Buka sheet Profil_Aplikasi, isi bagian A (nama, tujuan, teknologi, cara kerja, ruang lingkup). 1–2 kalimat per baris sudah cukup. • Tidak punya aplikasi? Tanyakan dosen sebelum mulai.
B15: Langkah 3 Daftar komponen dan aset | C15: • Profil_Aplikasi bagian B. Komponen = bagian aplikasi (halaman login, API, database, server, perangkat). Aset = sesuatu yang bernilai dan harus dilindungi (data pengguna, password, ketersediaan layanan). • Isi MINIMAL 4 komponen. Tiap baris: nama komponen, tugasnya, aset yang dilindungi, satu catatan keamanan yang Anda lihat. • Baris abu-abu 'Cth' hanyalah contoh dari aplikasi fiktif; bukan jawaban Anda.
B16: Langkah 4 Aliran data dan trust boundary | C16: • Profil_Aplikasi bagian C. Aliran data = data berpindah dari mana ke mana (mis. Browser → form login → database). Isi MINIMAL 4 aliran. • Bagian D. Trust boundary = garis tempat data pindah dari pihak yang kurang dipercaya ke bagian dalam sistem (mis. browser pengguna → server; aplikasi → database). Ancaman paling sering muncul di titik ini. Isi MINIMAL 2. • Bagian E (dianjurkan): gambar sketsa DFD sederhana lalu tempel di sheet. Kotak = komponen, panah = aliran data, garis putus-putus merah = trust boundary.
B17: Langkah 5 Cari ancaman | C17: • Ambil satu aliran data atau satu komponen. Ajukan 6 pertanyaan STRIDE kepadanya (daftar pertanyaan: STRIDE_Guidelines kolom F). Jawaban 'ya, mungkin terjadi' = calon ancaman. • Catat dulu kasar di kertas. Kumpulkan 8–12 calon, lalu pilih yang paling nyata untuk aplikasi Anda (minimal 6). • Ancaman harus KHUSUS aplikasi Anda: sebut nama halaman, fitur, tabel, atau file.
B18: Langkah 6 Tulis ancaman (kolom A–C) | C18: • Buka sheet STRIDE_DREAD_Template. Kolom ID: T-01, T-02, dst (atau nomor CVE bila memakai CVE nyata). • Kolom Deskripsi: tulis SATU kalimat dengan rumus [Siapa] + [melakukan apa] + [pada bagian mana] + [sehingga akibatnya apa]. Contoh: 'Penyerang di jaringan kampus menebak password lewat form login yang tidak membatasi percobaan, sehingga akun mahasiswa diambil alih.' • Jangan hanya menulis nama serangan seperti 'SQL Injection' tanpa konteks.
B19: Langkah 7 Tandai STRIDE (kolom D–I) | C19: • Klik sel, pilih 1 bila kategori itu benar-benar terjadi, 0 bila tidak. • Kebanyakan ancaman cukup 1–2 kategori. Empat atau lebih biasanya tanda Anda terlalu longgar. • Hati-hati dengan E (Elevation of Privilege): hanya bila hak akses NAIK (pengguna biasa menjadi admin). Membaca data orang lain = I, mengubah data = T, menyamar jadi orang lain = S. • Kolom Jumlah STRIDE terisi otomatis.
B20: Langkah 8 Beri skor DREAD (kolom K–O) | C20: • Beri angka bulat 0–10 untuk 5 dimensi, SATU PER SATU, dengan membaca pertanyaan penuntun di DREAD_Guidelines (0–2 rendah · 3–5 sedang · 6–8 tinggi · 9–10 sangat tinggi). • Jangan memberi 'tinggi semua' hanya karena ancamannya terdengar seram. Bandingkan antar ancaman: mana yang benar-benar paling parah dan paling mudah? • Total DREAD, Level Risiko, dan Prioritas muncul otomatis setelah kelima skor terisi.
B21: Langkah 9 Alasan, bukti, saran (kolom S–U) | C21: • Alasan skor (S): satu kalimat per dimensi mengapa angkanya segitu. Format: 'Damage 7: …; Reproducibility 9: …'. Tulis juga asumsi Anda. • Bukti (T): dari mana Anda tahu. Nama file + nomor baris, URL halaman, pengaturan server, atau tangkapan layar. • Saran mitigasi (U): 1–2 tindakan konkret untuk memperbaiki, mis. 'batasi 5 percobaan login per 10 menit; tambah CAPTCHA'. • Skor tanpa alasan dan bukti dianggap tebakan.
B22: Langkah 10 Periksa sendiri | C22: • Buka sheet Pemeriksa_Mandiri. Perbaiki semua butir yang bertanda PERIKSA sampai menjadi OK. • Lihat sheet Ringkasan: apakah levelnya bervariasi (tidak semua CRITICAL atau semua HIGH)? • Baca ulang 3 ancaman teratas: masuk akal sebagai prioritas 1–3 untuk aplikasi Anda?
B23: Langkah 11 Simpan dan kumpulkan | C23: • Simpan (Ctrl+S) dengan nama NPM_Nama_STRIDE-DREAD.xlsx, kecuali dosen menentukan lain. • Jangan menghapus atau mengganti nama sheet. Kumpulkan sesuai instruksi dosen.
B25: ARTI WARNA DAN KUNCI SHEET
B26: Warna sel | C26: Kuning muda = ISI SENDIRI · Abu-abu = rumus otomatis (terkunci) · Biru = STRIDE · Oranye = DREAD · Hijau = hasil otomatis · Putih bergaris = penjelasan.
B27: Skala level risiko | C27: Total DREAD 0–50: CRITICAL ≥ 40 · HIGH 30–39 · MEDIUM 20–29 · LOW < 20.
B28: Sheet dikunci | C28: Sheet dikunci (tanpa password) agar rumus tidak terhapus secara tidak sengaja; hanya sel kuning yang dapat diisi. Lebar kolom dan tinggi baris tetap boleh Anda ubah. Jangan membuka kunci kecuali terpaksa; rumus yang rusak membuat total tidak terhitung.
B30: KESALAHAN YANG PALING SERING TERJADI
B31: 1. Deskripsi terlalu umum | C31: Hanya menulis 'XSS' atau 'SQL Injection'. Perbaikan: sebut halaman atau fitur Anda dan akibatnya.
B32: 2. E dicentang di mana-mana | C32: E hanya untuk kenaikan hak akses. Perbaikan: baca lagi kolom G di STRIDE_Guidelines.
B33: 3. Skor DREAD tinggi semua atau sama semua | C33: Perbaikan: bandingkan antar ancaman; gunakan rentang level yang berbeda (ada MEDIUM atau LOW).
B34: 4. Tidak ada alasan dan bukti | C34: Perbaikan: isi kolom S dan T pada setiap baris, dengan merujuk berkas, baris kode, atau halaman.
B35: 5. Menyalin dari teman atau dari contoh | C35: Ancaman harus berasal dari aplikasi Anda sendiri. Isian yang mirip dengan isian lain dinilai rendah.
B36: 6. Menimpa sel abu-abu atau rumus | C36: Sel abu-abu terhitung otomatis. Bila ada yang aneh, jangan diedit; periksa isian kuning di baris yang sama.
B37: 7. Menyerang sistem sungguhan | C37: Praktikum ini ANALISIS (membaca kode, konfigurasi, dan alur). Uji hanya pada aplikasi milik sendiri atau lingkungan latihan. Jangan menyerang sistem milik orang lain.
B39: JIKA MACET
B40: Tidak tahu mulai dari mana | C40: Mulai dari fitur login, form input, unggah file, API, database, dan konfigurasi server. Tanyakan 6 pertanyaan STRIDE pada masing-masing.
B41: Ragu memilih STRIDE | C41: Tanyakan: apa yang dilanggar? Autentikasi → S · Integritas → T · Bukti → R · Kerahasiaan → I · Ketersediaan → D · Otorisasi → E.
B42: Ragu memberi skor | C42: Bandingkan dengan ancaman lain milik Anda: yang lebih parah dapat angka lebih tinggi. Tulis asumsi di kolom Alasan skor; asumsi yang jelas lebih baik daripada angka tanpa alasan.
B43: Masih macet | C43: Bawa pertanyaan bersama file yang sudah terisi sebagian ke dosen atau asisten.
B45: YANG AKAN DINILAI
B46: Kelengkapan isian (15) | C46: Profil_Aplikasi terisi; minimal 6 ancaman; ID, STRIDE, dan DREAD terisi lengkap.
B47: Kualitas deskripsi (30) | C47: Kalimat ancaman jelas (siapa, aksi, bagian, akibat) dan khusus untuk aplikasi Anda.
...

Sheet Contoh_Pengisian
B2: Contoh Pengisian (aplikasi fiktif: SIPUS)
B3: SIPUS = sistem peminjaman buku perpustakaan kampus berbasis web (PHP + MySQL). Mahasiswa meminjam lewat browser, petugas mengelola data. Contoh ini hanya untuk meniru CARA BERPIKIR dan FORMAT. Jangan menyalin isinya untuk aplikasi Anda.
B5: 1. TIGA CONTOH LENGKAP, DARI MENEMUKAN SAMPAI MENILAI
B7: Contoh 1 — Login tanpa batas percobaan (hasil: HIGH)
B8: ① Menemukan | C8: Saya melihat aliran data 'Browser → form login'. Pertanyaan STRIDE untuk aliran ini: 'Bisakah seseorang menyamar sebagai mahasiswa lain?' Jawabannya ya: password bisa ditebak berulang kali karena tidak ada batas percobaan.
B9: ② Menulis (kolom C) | C9: Penyerang di internet menebak password akun mahasiswa berulang kali lewat form login SIPUS yang tidak membatasi percobaan, sehingga akun mahasiswa diambil alih dan riwayat peminjamannya terbaca. → Siapa: penyerang di internet · Aksi: menebak password berulang · Bagian: form login SIPUS · Akibat: akun diambil alih, riwayat pinjam terbaca.
B10: ③ STRIDE (kolom D–I) | C10: S = 1 karena pelaku menyamar sebagai mahasiswa. I = 1 karena riwayat pinjam ikut terbaca. T, R, D = 0: tidak ada data diubah, tidak ada masalah bukti, layanan tetap hidup. E = 0: pelaku hanya menjadi mahasiswa biasa, tidak naik menjadi admin.
B11: ④ DREAD (kolom K–O) | C11: Damage 5: data pribadi satu akun bocor dan bisa dipakai meminjam atas nama korban, tetapi sistem tidak rusak. Reproducibility 9: bisa diulang kapan saja dengan skrip sederhana. Exploitability 7: perlu alat otomatis dan daftar password umum, tanpa akses khusus. Affected Users 5: satu akun per keberhasilan, tetapi dapat diulang ke banyak akun. Discoverability 8: form login terlihat publik dan tidak tampak ada pembatasan.
B12: ⑤ Hasil di template | C12: S | D12: T | E12: R | F12: I | G12: D | H12: E | I12: Jumlah | J12: Damage | K12: Repro. | L12: Exploit. | M12: Affected | N12: Discover. | O12: Total | P12: Level
B13: C-01 | C13: 1 | D13: 0 | E13: 0 | F13: 1 | G13: 0 | H13: 0 | I13: =SUM(C13:H13) -> 2 | J13: 5 | K13: 9 | L13: 7 | M13: 5 | N13: 8 | O13: =SUM(J13:N13) -> 34 | P13: =IF(O13="","",IF(O13>=DREAD_Guidelines!$B$13,"CRITICAL",IF(O13>=DREAD_Guidelines!$B$14,"HIGH",IF(O13>=DREAD_Guidelines!$B$15,"MEDIUM","LOW")))) -> HIGH
B14: ⑥ Alasan, bukti, saran (kolom S–U) | C14: Alasan skor: Damage 5: data satu akun bocor, sistem tidak rusak; Reproducibility 9: dapat diulang dengan skrip; Exploitability 7: butuh alat dan daftar password; Affected 5: satu akun per berhasil; Discoverability 8: form login publik. Bukti: login.php baris 12–25: hanya membandingkan password, tanpa penghitung percobaan atau CAPTCHA. (Dibaca dari kode, tidak diserang.) Saran mitigasi: Batasi 5 percobaan gagal per 10 menit per akun dan per IP; tambahkan CAPTCHA setelah 3 kali gagal; kunci akun sementara dan kirim pemberitahuan.
B16: Contoh 2 — Lalu lintas login tanpa HTTPS (hasil: MEDIUM)
B17: ① Menemukan | C17: Saya melihat aliran 'Petugas → halaman admin' memakai alamat http://. Pertanyaan STRIDE: 'Bisakah pihak lain MELIHAT data rahasia di jalan?' Jawabannya ya.
B18: ② Menulis (kolom C) | C18: Penyerang yang berada di WiFi kampus yang sama menyadap lalu lintas HTTP (tanpa HTTPS) ke SIPUS, sehingga password petugas perpustakaan terbaca dan akun petugas dapat dipakai. → Siapa: penyerang di WiFi yang sama · Aksi: menyadap lalu lintas HTTP · Bagian: login petugas · Akibat: password terbaca, akun dipakai.
B19: ③ STRIDE (kolom D–I) | C19: I = 1 karena password terbaca di jaringan. S = 1 karena password itu lalu dipakai menyamar sebagai petugas. E = 0: penyerang memakai hak petugas yang memang ada; ia tidak menaikkan hak sendiri.
B20: ④ DREAD (kolom K–O) | C20: Damage 7: akun petugas dapat mengubah atau menghapus data pinjaman. Reproducibility 5: berhasil bila penyerang ada di jaringan yang sama saat petugas login. Exploitability 4: butuh posisi di jaringan yang sama dan alat penyadap. Affected Users 8: data seluruh mahasiswa berada di bawah kendali akun petugas. Discoverability 4: penyerang perlu tahu bahwa situs memakai HTTP dan kapan petugas login.
B21: ⑤ Hasil di template | C21: S | D21: T | E21: R | F21: I | G21: D | H21: E | I21: Jumlah | J21: Damage | K21: Repro. | L21: Exploit. | M21: Affected | N21: Discover. | O21: Total | P21: Level
B22: C-02 | C22: 1 | D22: 0 | E22: 0 | F22: 1 | G22: 0 | H22: 0 | I22: =SUM(C22:H22) -> 2 | J22: 7 | K22: 5 | L22: 4 | M22: 8 | N22: 4 | O22: =SUM(J22:N22) -> 28 | P22: =IF(O22="","",IF(O22>=DREAD_Guidelines!$B$13,"CRITICAL",IF(O22>=DREAD_Guidelines!$B$14,"HIGH",IF(O22>=DREAD_Guidelines!$B$15,"MEDIUM","LOW")))) -> MEDIUM
B23: ⑥ Alasan, bukti, saran (kolom S–U) | C23: Alasan skor: Damage 7: akun petugas dapat mengubah data; Reproducibility 5: hanya saat penyerang satu jaringan; Exploitability 4: butuh posisi jaringan + alat; Affected 8: data semua mahasiswa; Discoverability 4: harus tahu kapan login. Bukti: Alamat sistem diawali http://, browser menampilkan 'Tidak aman'; konfigurasi Apache tidak mengaktifkan SSL (httpd-ssl.conf tidak dimuat). Saran mitigasi: Aktifkan HTTPS (TLS) dan HSTS; alihkan semua HTTP ke HTTPS; beri flag Secure dan HttpOnly pada cookie sesi.
B25: Contoh 3 — Penghapusan data tanpa catatan (hasil: LOW)
B26: ① Menemukan | C26: Saya melihat aliran 'Petugas → hapus_pinjam.php'. Pertanyaan STRIDE: 'Jika petugas menghapus data, adakah catatan yang membuktikan siapa pelakunya?' Jawabannya tidak ada.
B27: ② Menulis (kolom C) | C27: Petugas perpustakaan yang menghapus data peminjaman dapat menyangkalnya karena SIPUS tidak mencatat siapa, kapan, dan data apa yang dihapus, sehingga sengketa denda tidak dapat dibuktikan. → Siapa: petugas perpustakaan · Aksi: menghapus data lalu menyangkal · Bagian: fitur hapus peminjaman · Akibat: sengketa denda tak bisa dibuktikan.
B28: ③ STRIDE (kolom D–I) | C28: Hanya R = 1: masalahnya adalah TIDAK ADA BUKTI. T tidak saya tandai karena fokus ancaman ini bukan perubahan data oleh orang tidak berhak, melainkan pelaku yang tak dapat dilacak.
B29: ④ DREAD (kolom K–O) | C29: Damage 4: sistem tidak rusak, tetapi bukti untuk sengketa hilang. Reproducibility 6: terjadi setiap kali ada penghapusan. Exploitability 3: pelaku harus memiliki akun petugas. Affected Users 3: hanya mahasiswa yang sedang bersengketa. Discoverability 2: baru terlihat ketika ada sengketa dan seseorang mencari lognya.
B30: ⑤ Hasil di template | C30: S | D30: T | E30: R | F30: I | G30: D | H30: E | I30: Jumlah | J30: Damage | K30: Repro. | L30: Exploit. | M30: Affected | N30: Discover. | O30: Total | P30: Level
B31: C-03 | C31: 0 | D31: 0 | E31: 1 | F31: 0 | G31: 0 | H31: 0 | I31: =SUM(C31:H31) -> 1 | J31: 4 | K31: 6 | L31: 3 | M31: 3 | N31: 2 | O31: =SUM(J31:N31) -> 18 | P31: =IF(O31="","",IF(O31>=DREAD_Guidelines!$B$13,"CRITICAL",IF(O31>=DREAD_Guidelines!$B$14,"HIGH",IF(O31>=DREAD_Guidelines!$B$15,"MEDIUM","LOW")))) -> LOW
B32: ⑥ Alasan, bukti, saran (kolom S–U) | C32: Alasan skor: Damage 4: bukti sengketa hilang, sistem tidak rusak; Reproducibility 6: setiap penghapusan; Exploitability 3: butuh akun petugas; Affected 3: mahasiswa yang bersengketa; Discoverability 2: baru terlihat saat sengketa. Bukti: hapus_pinjam.php baris 8–10: hanya menjalankan DELETE; tidak ada tabel log pada skema database (daftar tabel: mahasiswa, buku, pinjaman). Saran mitigasi: Buat tabel audit_log (user, aksi, waktu, id data); gunakan soft delete (tandai terhapus); hanya admin yang boleh melihat log.
B34: 2. URUTAN PRIORITAS DARI KETIGA CONTOH (dihitung otomatis)
B35: ID ancaman | C35: Total DREAD | F35: Prioritas (1 = tertinggi)
B36: C-01 | C36: =O13 -> 34 | F36: =RANK(C36,$C$36:$C$38,0) -> 1
B37: C-02 | C37: =O22 -> 28 | F37: =RANK(C37,$C$36:$C$38,0) -> 2
B38: C-03 | C38: =O31 -> 18 | F38: =RANK(C38,$C$36:$C$38,0) -> 3
B39: Prioritas 1 = total terbesar = diperbaiki lebih dulu. Dua ancaman dengan total sama mendapat peringkat yang sama. Di template, kolom Prioritas dihitung seperti ini dan Anda tidak perlu mengisinya.
B41: 3. TULISAN KURANG BAIK vs LEBIH BAIK
B42: Kolom | C42: Kurang baik | G42: Lebih baik | L42: Mengapa
B43: Deskripsi | C43: SQL Injection. | G43: Penyerang memasukkan perintah SQL pada kolom pencarian buku SIPUS, sehingga isi tabel mahasiswa dapat dibaca. | L43: Ada aktor, aksi, bagian aplikasi, dan akibat. Orang lain paham tanpa bertanya.
B44: STRIDE | C44: S, T, R, I, D, E semua 1 karena 'ini berbahaya'. | G44: I = 1 saja (data dibaca). T = 1 hanya jika data juga bisa diubah. | L44: Pilih kategori yang benar-benar terjadi; bukan semua yang terdengar buruk.
B45: Alasan skor | C45: Tinggi karena berbahaya. | G45: Damage 7: seluruh data mahasiswa terbaca; Reproducibility 9: URL yang sama selalu berhasil; … | L45: Satu kalimat per dimensi membuat skor dapat diperiksa dan dibantah.
B46: Bukti | C46: (kosong) | G46: cari.php baris 31: kueri disusun dengan menyambung string dari $_GET['q']. | L46: Bukti membedakan temuan nyata dari tebakan.
B47: Mitigasi | C47: Perbaiki keamanannya. | G47: Ganti dengan prepared statement; batasi hak akun database aplikasi hanya SELECT pada tabel buku. | L47: Saran harus bisa dikerjakan, bukan nasihat umum.
...

Sheet Profil_Aplikasi
A1: Profil Aplikasi Sasaran (isi dulu, sebelum menilai ancaman)
A2: Isi sel kuning. Baris abu-abu 'Cth' adalah CONTOH dari aplikasi fiktif perpustakaan (SIPUS), bukan jawaban Anda. Tulis singkat dan jelas; 1–2 kalimat per sel sudah cukup. Profil ini dipakai sebagai konteks untuk sheet STRIDE_DREAD_Template.
A4: A. Ringkasan sistem
A5: Nama sistem | B5: FindServices: Marketplace Layanan Jasa Lokal Terdekat (Laravel 12 + Inertia.js/Vue 3 + MySQL) | F5: Nama aplikasi + versi atau folder. Cth: 'SIPUS: peminjaman buku perpustakaan kampus (PHP + MySQL)'.
A6: Tujuan | B6: Aplikasi web marketplace untuk menghubungkan pelanggan (Customer) dengan penyedia jasa lokal (Provider/Tukang) berbasis radius jarak geolokasi (Haversine), negosiasi pemesanan, pembayaran Midtrans, dan chat real-time. | F6: Aplikasi ini dipakai untuk apa, dan oleh siapa? 1–2 kalimat.
A7: Teknologi | B7: Backend: Laravel 12 (PHP 8.3); Frontend: Vue 3 + Inertia.js + Tailwind CSS; Database: MySQL; Realtime: Laravel Reverb (WebSocket port 8080); Gateway: Midtrans Snap API; Tunnel: Cloudflare. | F7: Bahasa/framework, database, server, perangkat. Cth: 'PHP 8 + MySQL di Apache; front-end HTML + JavaScript'.
A8: Cara kerja ringkas | B8: Pelanggan mencari jasa berdasarkan kategori atau lokasi terdekat lalu membuat pesanan (booking). Penyedia jasa meninjau, menyepakati harga final, dan mengonfirmasi pesanan. Pelanggan membayar via Midtrans Gateway atau Tunai, berkomunikasi via chat real-time Reverb, dan memberikan ulasan setelah selesai. | F8: Ceritakan perjalanan data: pengguna melakukan apa → aplikasi memproses apa → data disimpan di mana. 3–4 kalimat.
A9: Ruang lingkup analisis | B9: Analisis arsitektur, konfigurasi environment (.env), dan source code backend (controller, route, model, middleware, events) repositori FindServices melalui static code review dan threat modeling tanpa melakukan serangan aktif (non-destructive). | F9: Bagian mana yang Anda analisis dan dari sumber apa (membaca kode, dokumentasi, mengamati). Tulis bahwa Anda TIDAK menyerang sistem.
A11: B. Komponen dan aset (isi minimal 4 baris)
A12: Komponen = bagian-bagian aplikasi. Aset = hal bernilai yang harus dilindungi. Catatan keamanan = kelemahan atau kekhawatiran yang Anda lihat, boleh singkat.
A13: ID | B13: Komponen | C13: Peran (tugasnya) | D13: Aset yang dilindungi | E13: Catatan keamanan singkat
A14: Cth | B14: Form login mahasiswa | C14: Memeriksa NPM dan password lalu membuat sesi | D14: Akun mahasiswa; kerahasiaan password | E14: Belum ada batas percobaan login
A15: K1 | B15: Modul Autentikasi & Akun (Auth & ProfileController) | C15: Registrasi, login sesi, update profil, dan upload avatar pengguna | D15: Kredensial akun, password hash bcrypt, token sesi, data profil pribadi | E15: Atribut 'role' sempat terbuka di mass assignment model User; SESSION_ENCRYPT default false
A16: K2 | B16: Modul Pemesanan & Alur Status (BookingController) | C16: Membuat booking, validasi kuota harian, konfirmasi status, dan deal harga final | D16: Integritas transaksi pesanan, validitas kesepakatan harga, jadwal kerja provider | E16: Pengecekan hak akses auth()->id() di updateStatus sempat dinonaktifkan (potensi BOLA/IDOR)
A17: K3 | B17: Modul Gateway Pembayaran (PaymentCallbackController) | C17: Request token Snap Midtrans dan memproses webhook callback status pembayaran | D17: Integritas status lunas booking, verifikasi finansial, Server Key Midtrans | E17: Route webhook CSRF-exempt; verifikasi SHA512 rentan bypass bila Server Key kosong di env
A18: K4 | B18: Modul Marketplace & Geolokasi (MarketplaceController) | C18: Katalog jasa dengan filter kategori, harga, rating, dan radius Haversine | D18: Ketersediaan layanan database server, privasi koordinat lokasi latitude/longitude | E18: Kalkulasi rumus Haversine intensif CPU tanpa caching database berisiko Denial of Service
A19: K5 | B19: Modul Manajemen Jasa & Galeri (ServiceController) | C19: Publikasi jasa, deskripsi layanan, tarif minimum/maksimum, dan galeri foto | D19: Integritas data katalog jasa publik, kapasitas penyimpanan disk server | E19: Batas upload 10MB hanya validasi tipe MIME dasar tanpa inspeksi mendalam file biner
A20: K6 | B20: Modul Percakapan Realtime (ChatController & Reverb) | C20: Pengiriman pesan teks instan, penandaan dibaca, dan soft delete pesan chat | D20: Kerahasiaan percakapan pribadi antar pengguna, ketersediaan daemon WebSocket | E20: Endpoint /api/test-latency tanpa autentikasi berpotensi membanjiri channel Reverb (DoS)
A21: K7 | B21: Modul Ulasan & Rating (Review & BookingController) | C21: Menyimpan penilaian rating bintang, ulasan teks, dan foto bukti pengerjaan jasa | D21: Reputasi provider, integritas skor rating jasa, konten review publik | E21: Input teks review rentan Stored XSS jika dirender mentah (v-html) tanpa sanitasi HTML
A22: K8 | B22: Modul Administrasi & Pengaduan (Admin Controllers) | C22: Manajemen kategori jasa, penanganan laporan keluhan user, dan restore data | D22: Hak akses administrator platform, integritas master kategori, data laporan pengaduan | E22: AdminMiddleware mengandalkan field role pada model User; route admin harus steril dari bypass
A23: K9 | B23: Modul Notifikasi Pengguna (NotificationController) | C23: Mengirim notifikasi pesanan, pembayaran, dan ulasan ke database dan email | D23: Kerahasiaan pemberitahuan transaksi, keandalan pengiriman antrean mail/notif | E23: Kredensial SMTP Gmail di .env harus dilindungi dari pembacaan pihak ketiga
A24: K10 | B24: Penyimpanan Database & Sesi (MySQL Database Engine) | C24: Menyimpan tabel users, services, bookings, chats, reviews, reports, dan sessions | D24: Integritas dan kerahasiaan seluruh rekaman basis data relasional aplikasi | E24: Perlu prepared statement konsisten dan enkripsi sesi agar terhindar dari SQLi dan session hijacking
A26: C. Aliran data (DFD level-0) (isi minimal 4 baris)
A27: Aliran data = data berpindah dari mana ke mana. Pada kolom terakhir tulis 'Ya (TB-1)' bila melewati trust boundary (lihat bagian D), atau 'Tidak'.
A28: ID | B28: Dari → ke | C28: Data yang mengalir | D28: Protokol | E28: Melewati trust boundary?
A29: Cth | B29: Browser mahasiswa → form login | C29: NPM dan password | D29: HTTP POST (belum HTTPS) | E29: Ya (TB-1)
A30: F1 | B30: Browser Customer -> Web Router (Form Login / Registrasi) | C30: Email, password, nama lengkap, nomor telepon, session cookie | D30: HTTPS (TLS via Cloudflare Tunnel) | E30: Ya (TB-1 ke TB-2)
A31: F2 | B31: Browser Customer -> MarketplaceController (Pencarian Jasa) | C31: Query keyword, filter kategori, koordinat latitude/longitude, radius km | D31: HTTPS GET | E31: Ya (TB-1 ke TB-2)
A32: F3 | B32: Browser Customer -> BookingController (Form Pemesanan Jasa) | C32: Service ID, tanggal booking, jam, lokasi alamat, catatan, metode bayar | D32: HTTPS POST | E32: Ya (TB-1 ke TB-2)
A33: F4 | B33: Browser Provider -> BookingController (Konfirmasi Status Pesanan) | C33: Booking ID, status baru (confirmed/in_progress), agreed_price deal | D33: HTTPS PATCH | E33: Ya (TB-1 ke TB-2)
A34: F5 | B34: BookingController -> Midtrans Snap API (Permintaan Token Bayar) | C34: Order ID unik, gross_amount (final_price + fee), identitas user, Server Key | D34: HTTPS POST (TLS 1.3) | E34: Ya (TB-3 ke TB-1)
A35: F6 | B35: Midtrans Gateway -> PaymentCallbackController (Webhook Callback) | C35: order_id, status_code, gross_amount, signature_key, transaction_status | D35: HTTP/HTTPS POST (/api/midtrans/callback) | E35: Ya (TB-1 ke TB-2)
A36: F7 | B36: Browser Pengguna -> ChatController (Kirim Pesan Chat) | C36: receiver_id (hashids), pesan teks, service_id, booking_id referensi | D36: HTTPS POST | E36: Ya (TB-1 ke TB-2)
A37: F8 | B37: Chat & Booking Controller -> Laravel Reverb (WebSocket Broadcast) | C37: Event MessageSent / BookingStatusUpdated, payload data JSON serial | D37: TCP WebSocket Internal (localhost:8080) | E37: Ya (TB-3 ke TB-4)
A38: F9 | B38: Controller Aplikasi -> MySQL Database (findservices) | C38: SQL queries (SELECT, INSERT, UPDATE tabel users, bookings, chats, reviews) | D38: TCP MySQL port 3306 | E38: Ya (TB-3 ke TB-5)
A39: F10 | B39: Controller Aplikasi -> Storage Disk Lokal (storage/app/public) | C39: File biner gambar avatar, galeri jasa, bukti laporan/review (.webp) | D39: Local Filesystem I/O | E39: Ya (TB-3 ke TB-5)
A41: D. Trust boundary (isi minimal 2 baris)
A42: Trust boundary = batas antara bagian yang dipercaya dan yang kurang dipercaya. Contoh: browser pengguna ↔ server; aplikasi ↔ database; aplikasi ↔ layanan pihak ketiga.
A43: ID | B43: Batas (bagian A ↔ bagian B) | C43: Mengapa penting
A44: Cth | B44: Browser mahasiswa ↔ server web | C44: Siapa pun di internet dapat mengirim request; server tidak boleh langsung percaya pada input.
...

Sheet STRIDE_DREAD_Template
A1: Template Praktikum STRIDE + DREAD
A2: Isi hanya sel kuning, dari kiri ke kanan, satu baris per ancaman. STRIDE: 1 = berlaku, 0 = tidak. DREAD: skor 0–10. Kolom abu-abu dan hijau terhitung otomatis. Bingung? Buka sheet Petunjuk dan Contoh_Pengisian.
A3: Identitas | D3: STRIDE (1 = ya, 0 = tidak) | K3: DREAD (skor 0–10) | P3: Hasil otomatis | S3: Penjelasan (wajib diisi)
A4: No | B4: ID Ancaman / CVE | C4: Deskripsi | D4: S Spoofing | E4: T Tampering | F4: R Repudiation | G4: I Info Disclosure | H4: D Denial of Service | I4: E Elevation of Privilege | J4: Jumlah STRIDE | K4: Damage (0–10) | L4: Reproducibility (0–10) | M4: Exploitability (0–10) | N4: Affected Users (0–10) | O4: Discoverability (0–10) | P4: Total DREAD (0–50) | Q4: Level Risiko | R4: Prioritas (1 = tertinggi) | S4: Alasan skor (1 kalimat per dimensi DREAD) | T4: Bukti / sumber (file + baris, URL, konfigurasi) | U4: Saran mitigasi (1–2 tindakan konkret)
A5: 1 | B5: T-01 (CVE-2023-28438) | C5: Penyerang yang terautentikasi memanipulasi parameter order_id pada endpoint status booking di BookingController tanpa verifikasi kepemilikan akun, sehingga dapat mengubah status pesanan milik pengguna lain secara sepihak. | D5: 0 | E5: 1 | F5: 0 | G5: 0 | H5: 0 | I5: 1 | J5: =IF(COUNT(D5:I5)=0,"",SUM(D5:I5)) -> 2 | K5: 8 | L5: 9 | M5: 8 | N5: 8 | O5: 7 | P5: =IF(COUNT(K5:O5)=5,SUM(K5:O5),"") -> 40 | Q5: =IF(P5="","",IF(P5>=DREAD_Guidelines!$B$13,"CRITICAL",IF(P5>=DREAD_Guidelines!$B$14,"HIGH",IF(P5>=DREAD_Guidelines!$B$15,"MEDIUM","LOW")))) -> CRITICAL | R5: =IF(P5="","",RANK(P5,$P$5:$P$44,0)) -> 1 | S5: Damage 8: penyerang dapat membatalkan atau mengubah sepihak status transaksi pengguna lain; Reproducibility 9: serangan sangat mudah diulang dengan mengganti parameter booking ID; Exploitability 8: dapat dieksekusi dengan request HTTP PATCH sederhana; Affected Users 8: berdampak pada seluruh pengguna aktif sistem; Discoverability 7: celah otorisasi mudah ditemukan melalui inspeksi endpoint API. | T5: BookingController.php baris 228–232: pengecekan hak akses kepemilikan auth()->id() dikomentari sehingga siapa pun dapat mengubah status booking. | U5: Aktifkan kembali validasi hak akses kepemilikan if (auth()->id() !== $booking->provider_id && auth()->id() !== $booking->customer_id) abort(403); dan gunakan Laravel Authorization Policy.
A6: 2 | B6: T-02 (CVE-2023-34449) | C6: Penyerang tanpa autentikasi mengirimkan ribuan request ke endpoint uji latensi WebSocket Reverb secara masif, sehingga membanjiri channel Reverb dan mengakibatkan server socket mengalami kehabisan memori serta lumpuh. | D6: 0 | E6: 0 | F6: 0 | G6: 0 | H6: 1 | I6: 0 | J6: =IF(COUNT(D6:I6)=0,"",SUM(D6:I6)) -> 1 | K6: 7 | L6: 9 | M6: 9 | N6: 8 | O6: 7 | P6: =IF(COUNT(K6:O6)=5,SUM(K6:O6),"") -> 40 | Q6: =IF(P6="","",IF(P6>=DREAD_Guidelines!$B$13,"CRITICAL",IF(P6>=DREAD_Guidelines!$B$14,"HIGH",IF(P6>=DREAD_Guidelines!$B$15,"MEDIUM","LOW")))) -> CRITICAL | R6: =IF(P6="","",RANK(P6,$P$5:$P$44,0)) -> 1 | S6: Damage 7: melumpuhkan fitur chat dan notifikasi real-time bagi seluruh pengguna; Reproducibility 9: sangat mudah diulang menggunakan script load testing; Exploitability 9: endpoint terbuka untuk publik tanpa autentikasi; Affected Users 8: memengaruhi seluruh pengguna yang mengandalkan real-time event; Discoverability 7: endpoint /api/test-latency tercantum jelas pada routes/api.php. | T6: routes/api.php baris 15–52: route POST /test-latency memicu TestLatency::dispatch tanpa middleware auth maupun rate limiting. | U6: Hapus route /test-latency pada lingkungan production atau lindungi dengan middleware auth:sanctum dan throttle rate limit 5 request per menit.
A7: 3 | B7: T-03 (CVE-2023-45133) | C7: Penyerang memalsukan notifikasi callback webhook Midtrans dengan mengeksploitasi kemungkinan kunci rahasia kosong pada berkas konfigurasi, sehingga status pembayaran booking berubah menjadi lunas tanpa transfer uang sesungguhnya. | D7: 1 | E7: 1 | F7: 0 | G7: 0 | H7: 0 | I7: 0 | J7: =IF(COUNT(D7:I7)=0,"",SUM(D7:I7)) -> 2 | K7: 9 | L7: 8 | M7: 7 | N7: 8 | O7: 7 | P7: =IF(COUNT(K7:O7)=5,SUM(K7:O7),"") -> 39 | Q7: =IF(P7="","",IF(P7>=DREAD_Guidelines!$B$13,"CRITICAL",IF(P7>=DREAD_Guidelines!$B$14,"HIGH",IF(P7>=DREAD_Guidelines!$B$15,"MEDIUM","LOW")))) -> HIGH | R7: =IF(P7="","",RANK(P7,$P$5:$P$44,0)) -> 3 | S7: Damage 9: menimbulkan kerugian finansial langsung karena pesanan dianggap lunas tanpa pembayaran riil; Reproducibility 8: mudah diulang dengan replay packet HTTP POST; Exploitability 7: membutuhkan pengetahuan format payload Midtrans; Affected Users 8: berdampak pada penyedia jasa dan platform; Discoverability 7: route webhook dikecualikan dari proteksi CSRF di bootstrap/app.php. | T7: PaymentCallbackController.php baris 14–38 dan bootstrap/app.php baris 21–23: route api/midtrans/callback dikecualikan dari CSRF dan .env membiarkan MIDTRANS_SERVER_KEY kosong secara default. | U7: Validasi ketat konfigurasi MIDTRANS_SERVER_KEY tidak boleh kosong, verifikasi ulang status transaksi langsung ke API Get Status Midtrans, dan catat log audit transaksi.
A8: 4 | B8: T-04 (CVE-2023-38035) | C8: Pengguna jahat memicu pencarian katalog dengan koordinat radius geolokasi secara berulang dan mengunggah banyak berkas berukuran 10MB, sehingga membebani CPU database dan menghabiskan ruang penyimpanan server. | D8: 0 | E8: 0 | F8: 0 | G8: 0 | H8: 1 | I8: 0 | J8: =IF(COUNT(D8:I8)=0,"",SUM(D8:I8)) -> 1 | K8: 7 | L8: 8 | M8: 8 | N8: 8 | O8: 7 | P8: =IF(COUNT(K8:O8)=5,SUM(K8:O8),"") -> 38 | Q8: =IF(P8="","",IF(P8>=DREAD_Guidelines!$B$13,"CRITICAL",IF(P8>=DREAD_Guidelines!$B$14,"HIGH",IF(P8>=DREAD_Guidelines!$B$15,"MEDIUM","LOW")))) -> HIGH | R8: =IF(P8="","",RANK(P8,$P$5:$P$44,0)) -> 4 | S8: Damage 7: menurunkan responsivitas server dan berisiko server crash karena kehabisan ruang disk; Reproducibility 8: dapat diulang otomatis dengan skrip bot HTTP; Exploitability 8: dapat dilakukan oleh siapa saja yang memiliki akun; Affected Users 8: seluruh pengguna mengalami kelambatan akses; Discoverability 7: batas upload 10MB dan endpoint pencarian publik terlihat langsung di UI. | T8: MarketplaceController.php baris 57–68: query rumus Haversine tanpa indexing spasial dan ProfileUpdateRequest.php / ServiceController.php: batas upload mencapai 10240 KB (10MB) per file. | U8: Terapkan caching hasil pencarian geolokasi (Redis/Database), turunkan batas maksimal upload menjadi 2MB, dan pasang rate limiting pada endpoint marketplace.
A9: 5 | B9: T-05 (CVE-2024-21501) | C9: Pengguna menyisipkan skrip berbahaya berupa payload JavaScript pada kolom ulasan review atau catatan pemesanan jasa, sehingga skrip dieksekusi di browser penyedia jasa atau administrator saat membuka halaman. | D9: 0 | E9: 1 | F9: 0 | G9: 1 | H9: 0 | I9: 0 | J9: =IF(COUNT(D9:I9)=0,"",SUM(D9:I9)) -> 2 | K9: 7 | L9: 8 | M9: 7 | N9: 8 | O9: 7 | P9: =IF(COUNT(K9:O9)=5,SUM(K9:O9),"") -> 37 | Q9: =IF(P9="","",IF(P9>=DREAD_Guidelines!$B$13,"CRITICAL",IF(P9>=DREAD_Guidelines!$B$14,"HIGH",IF(P9>=DREAD_Guidelines!$B$15,"MEDIUM","LOW")))) -> HIGH | R9: =IF(P9="","",RANK(P9,$P$5:$P$44,0)) -> 5 | S9: Damage 7: pencurian sesi token admin/provider atau pengalihan halaman; Reproducibility 8: tersimpan permanen di database dan dieksekusi setiap halaman dibuka; Exploitability 7: membutuhkan keahlian injeksi script dasar; Affected Users 8: berdampak pada semua user yang melihat ulasan/booking tersebut; Discoverability 7: kolom input teks review terbuka luas. | T9: BookingController.php baris 470–502: kolom comment review hanya divalidasi string|max:500 tanpa pembersihan tag HTML (strip_tags atau htmlspecialchars). | U9: Terapkan sanitasi input menggunakan strip_tags() pada backend dan pastikan komponen Vue tidak menggunakan direktif v-html pada rendering konten ulasan.
A10: 6 | B10: T-06 (CVE-2023-22809) | C10: Pengguna mendaftar atau memperbarui profil lalu menambahkan parameter role=admin melalui manipulasi HTTP request payload, sehingga hak akses akun meningkat menjadi administrator karena atribut role masuk ke fillable model. | D10: 0 | E10: 1 | F10: 0 | G10: 0 | H10: 0 | I10: 1 | J10: =IF(COUNT(D10:I10)=0,"",SUM(D10:I10)) -> 2 | K10: 9 | L10: 8 | M10: 7 | N10: 7 | O10: 6 | P10: =IF(COUNT(K10:O10)=5,SUM(K10:O10),"") -> 37 | Q10: =IF(P10="","",IF(P10>=DREAD_Guidelines!$B$13,"CRITICAL",IF(P10>=DREAD_Guidelines!$B$14,"HIGH",IF(P10>=DREAD_Guidelines!$B$15,"MEDIUM","LOW")))) -> HIGH | R10: =IF(P10="","",RANK(P10,$P$5:$P$44,0)) -> 5 | S10: Damage 9: penyerang memperoleh hak akses penuh mengelola kategori, laporan, dan data seluruh sistem; Reproducibility 8: dapat diulang pada endpoint modifikasi profil; Exploitability 7: membutuhkan pengiriman raw JSON request; Affected Users 7: integritas seluruh sistem terdampak; Discoverability 6: celah mass assignment dapat diprediksi dari struktur Eloquent standar. | T10: app/Models/User.php baris 26: kolom 'role' terdaftar di properti protected $fillable User model. | U10: Keluarkan atribut 'role' dari array $fillable pada model User, dan atur penetapan role hanya melalui seeder atau controller admin khusus.
A11: 7 | B11: T-07 (CVE-2024-21516) | C11: Pengguna mengunggah berkas gambar manipulasi (seperti polyglot file atau SVG berbisa) pada fitur foto jasa dan avatar profil, sehingga berkas berbahaya tersimpan di direktori publik server dan dapat memicu SSRF atau XSS. | D11: 0 | E11: 1 | F11: 0 | G11: 1 | H11: 0 | I11: 0 | J11: =IF(COUNT(D11:I11)=0,"",SUM(D11:I11)) -> 2 | K11: 8 | L11: 7 | M11: 6 | N11: 7 | O11: 6 | P11: =IF(COUNT(K11:O11)=5,SUM(K11:O11),"") -> 34 | Q11: =IF(P11="","",IF(P11>=DREAD_Guidelines!$B$13,"CRITICAL",IF(P11>=DREAD_Guidelines!$B$14,"HIGH",IF(P11>=DREAD_Guidelines!$B$15,"MEDIUM","LOW")))) -> HIGH | R11: =IF(P11="","",RANK(P11,$P$5:$P$44,0)) -> 7 | S11: Damage 8: potensi eksekusi script atau pembacaan file internal server; Reproducibility 7: berhasil selama berkas lolos filter ekstensi mime; Exploitability 6: membutuhkan crafting payload file khusus; Affected Users 7: pengunjung dan server berisiko terdampak; Discoverability 6: fitur upload media tersedia di berbagai modul. | T11: ServiceController.php baris 63–64 dan UserReportController.php baris 36: validasi hanya memeriksa ekstensi mimes tanpa verifikasi magic bytes konten gambar. | U11: Gunakan pustaka image processing (seperti Intervention Image) untuk merender ulang dan mengonversi semua gambar ke WebP/JPEG murni, serta nonaktifkan eksekusi skrip di folder storage.
A12: 8 | B12: T-08 (CVE-2022-31129) | C12: Pihak ketiga pada jaringan lokal atau perantara sniffing mencuri session ID pengguna karena konfigurasi sesi di database tidak dienkripsi, sehingga penyerang dapat membajak sesi login pengguna tanpa memerlukan password. | D12: 1 | E12: 0 | F12: 0 | G12: 1 | H12: 0 | I12: 0 | J12: =IF(COUNT(D12:I12)=0,"",SUM(D12:I12)) -> 2 | K12: 8 | L12: 7 | M12: 6 | N12: 7 | O12: 6 | P12: =IF(COUNT(K12:O12)=5,SUM(K12:O12),"") -> 34 | Q12: =IF(P12="","",IF(P12>=DREAD_Guidelines!$B$13,"CRITICAL",IF(P12>=DREAD_Guidelines!$B$14,"HIGH",IF(P12>=DREAD_Guidelines!$B$15,"MEDIUM","LOW")))) -> HIGH | R12: =IF(P12="","",RANK(P12,$P$5:$P$44,0)) -> 7 | S12: Damage 8: akun korban diambil alih sepenuhnya selama sesi masih valid; Reproducibility 7: dapat diulang jika penyerang memperoleh token sesi; Exploitability 6: membutuhkan akses sniffing atau kebocoran database; Affected Users 7: memengaruhi pengguna yang sedang login aktif; Discoverability 6: konfigurasi .env SESSION_ENCRYPT=false dapat diketahui dari audit sistem. | T12: .env baris 34–36: SESSION_DRIVER=database dan SESSION_ENCRYPT=false menyimpan payload sesi secara plaintext di tabel sessions. | U12: Ubah konfigurasi .env menjadi SESSION_ENCRYPT=true dan pastikan flag cookie HttpOnly serta Secure aktif di config/session.php.
A13: 9 | B13: T-09 (CVE-2022-31279) | C13: Pengguna yang terautentikasi memanipulasi parameter hash_id pada URL percakapan atau request penghapusan pesan, sehingga dapat membaca pesan rahasia atau menghapus riwayat chat milik pihak lain tanpa izin. | D13: 0 | E13: 1 | F13: 0 | G13: 1 | H13: 0 | I13: 0 | J13: =IF(COUNT(D13:I13)=0,"",SUM(D13:I13)) -> 2 | K13: 6 | L13: 8 | M13: 7 | N13: 6 | O13: 6 | P13: =IF(COUNT(K13:O13)=5,SUM(K13:O13),"") -> 33 | Q13: =IF(P13="","",IF(P13>=DREAD_Guidelines!$B$13,"CRITICAL",IF(P13>=DREAD_Guidelines!$B$14,"HIGH",IF(P13>=DREAD_Guidelines!$B$15,"MEDIUM","LOW")))) -> HIGH | R13: =IF(P13="","",RANK(P13,$P$5:$P$44,0)) -> 9 | S13: Damage 6: kerahasiaan negosiasi dan privasi chat bocor atau hilang; Reproducibility 8: mudah diulang dengan men-decode pola Hashids; Exploitability 7: membutuhkan tebakan atau manipulasi hash parameter; Affected Users 6: terbatas pada pasangan chat yang disasar; Discoverability 6: parameter hash_id tampak jelas pada URL query string. | T13: ChatController.php baris 59–97 dan baris 240–253: pemuatan pesan konteks dan validasi kepemilikan mengandalkan decode hash tanpa policy terpusat. | U13: Gunakan Laravel Policy untuk memeriksa relasi pesan sebelum memuat atau menghapus chat, dan jangan jadikan Hashids sebagai satu-satunya lapisan keamanan otorisasi.
A14: 10 | B14: T-10 (CVE-2023-40028) | C14: [TERMITIGASI] Pengunjung website memicu error sistem untuk melihat tampilan stack trace lengkap dan kredensial sensitif, namun saat ini risiko telah diminimalisasi karena parameter APP_DEBUG telah dinonaktifkan di berkas .env. | D14: 0 | E14: 0 | F14: 0 | G14: 1 | H14: 0 | I14: 0 | J14: =IF(COUNT(D14:I14)=0,"",SUM(D14:I14)) -> 1 | K14: 2 | L14: 1 | M14: 1 | N14: 1 | O14: 1 | P14: =IF(COUNT(K14:O14)=5,SUM(K14:O14),"") -> 6 | Q14: =IF(P14="","",IF(P14>=DREAD_Guidelines!$B$13,"CRITICAL",IF(P14>=DREAD_Guidelines!$B$14,"HIGH",IF(P14>=DREAD_Guidelines!$B$15,"MEDIUM","LOW")))) -> LOW | R14: =IF(P14="","",RANK(P14,$P$5:$P$44,0)) -> 10 | S14: Damage 2: sistem hanya menampilkan halaman error 500 generik tanpa membocorkan data; Reproducibility 1: tidak lagi dapat direproduksi di lingkungan publik; Exploitability 1: tidak ada data sensitif yang diekspos di browser; Affected Users 1: tidak ada pengguna yang terdampak; Discoverability 1: pemindaian otomatis tidak lagi menemukan celah debug. | T14: .env baris 4: parameter APP_DEBUG telah diatur bernilai false (APP_DEBUG=false) sehingga stack trace dan environment variables terlindungi. | U14: Pertahankan APP_DEBUG=false pada lingkungan production, aktifkan log rotasi, dan gunakan sentry atau monitoring tertutup untuk pelacakan exception.
A15: 11 | J15: =IF(COUNT(D15:I15)=0,"",SUM(D15:I15)) | P15: =IF(COUNT(K15:O15)=5,SUM(K15:O15),"") | Q15: =IF(P15="","",IF(P15>=DREAD_Guidelines!$B$13,"CRITICAL",IF(P15>=DREAD_Guidelines!$B$14,"HIGH",IF(P15>=DREAD_Guidelines!$B$15,"MEDIUM","LOW")))) | R15: =IF(P15="","",RANK(P15,$P$5:$P$44,0))
A16: 12 | J16: =IF(COUNT(D16:I16)=0,"",SUM(D16:I16)) | P16: =IF(COUNT(K16:O16)=5,SUM(K16:O16),"") | Q16: =IF(P16="","",IF(P16>=DREAD_Guidelines!$B$13,"CRITICAL",IF(P16>=DREAD_Guidelines!$B$14,"HIGH",IF(P16>=DREAD_Guidelines!$B$15,"MEDIUM","LOW")))) | R16: =IF(P16="","",RANK(P16,$P$5:$P$44,0))
A17: 13 | J17: =IF(COUNT(D17:I17)=0,"",SUM(D17:I17)) | P17: =IF(COUNT(K17:O17)=5,SUM(K17:O17),"") | Q17: =IF(P17="","",IF(P17>=DREAD_Guidelines!$B$13,"CRITICAL",IF(P17>=DREAD_Guidelines!$B$14,"HIGH",IF(P17>=DREAD_Guidelines!$B$15,"MEDIUM","LOW")))) | R17: =IF(P17="","",RANK(P17,$P$5:$P$44,0))
A18: 14 | J18: =IF(COUNT(D18:I18)=0,"",SUM(D18:I18)) | P18: =IF(COUNT(K18:O18)=5,SUM(K18:O18),"") | Q18: =IF(P18="","",IF(P18>=DREAD_Guidelines!$B$13,"CRITICAL",IF(P18>=DREAD_Guidelines!$B$14,"HIGH",IF(P18>=DREAD_Guidelines!$B$15,"MEDIUM","LOW")))) | R18: =IF(P18="","",RANK(P18,$P$5:$P$44,0))
A19: 15 | J19: =IF(COUNT(D19:I19)=0,"",SUM(D19:I19)) | P19: =IF(COUNT(K19:O19)=5,SUM(K19:O19),"") | Q19: =IF(P19="","",IF(P19>=DREAD_Guidelines!$B$13,"CRITICAL",IF(P19>=DREAD_Guidelines!$B$14,"HIGH",IF(P19>=DREAD_Guidelines!$B$15,"MEDIUM","LOW")))) | R19: =IF(P19="","",RANK(P19,$P$5:$P$44,0))
A20: 16 | J20: =IF(COUNT(D20:I20)=0,"",SUM(D20:I20)) | P20: =IF(COUNT(K20:O20)=5,SUM(K20:O20),"") | Q20: =IF(P20="","",IF(P20>=DREAD_Guidelines!$B$13,"CRITICAL",IF(P20>=DREAD_Guidelines!$B$14,"HIGH",IF(P20>=DREAD_Guidelines!$B$15,"MEDIUM","LOW")))) | R20: =IF(P20="","",RANK(P20,$P$5:$P$44,0))
A21: 17 | J21: =IF(COUNT(D21:I21)=0,"",SUM(D21:I21)) | P21: =IF(COUNT(K21:O21)=5,SUM(K21:O21),"") | Q21: =IF(P21="","",IF(P21>=DREAD_Guidelines!$B$13,"CRITICAL",IF(P21>=DREAD_Guidelines!$B$14,"HIGH",IF(P21>=DREAD_Guidelines!$B$15,"MEDIUM","LOW")))) | R21: =IF(P21="","",RANK(P21,$P$5:$P$44,0))
A22: 18 | J22: =IF(COUNT(D22:I22)=0,"",SUM(D22:I22)) | P22: =IF(COUNT(K22:O22)=5,SUM(K22:O22),"") | Q22: =IF(P22="","",IF(P22>=DREAD_Guidelines!$B$13,"CRITICAL",IF(P22>=DREAD_Guidelines!$B$14,"HIGH",IF(P22>=DREAD_Guidelines!$B$15,"MEDIUM","LOW")))) | R22: =IF(P22="","",RANK(P22,$P$5:$P$44,0))
A23: 19 | J23: =IF(COUNT(D23:I23)=0,"",SUM(D23:I23)) | P23: =IF(COUNT(K23:O23)=5,SUM(K23:O23),"") | Q23: =IF(P23="","",IF(P23>=DREAD_Guidelines!$B$13,"CRITICAL",IF(P23>=DREAD_Guidelines!$B$14,"HIGH",IF(P23>=DREAD_Guidelines!$B$15,"MEDIUM","LOW")))) | R23: =IF(P23="","",RANK(P23,$P$5:$P$44,0))
A24: 20 | J24: =IF(COUNT(D24:I24)=0,"",SUM(D24:I24)) | P24: =IF(COUNT(K24:O24)=5,SUM(K24:O24),"") | Q24: =IF(P24="","",IF(P24>=DREAD_Guidelines!$B$13,"CRITICAL",IF(P24>=DREAD_Guidelines!$B$14,"HIGH",IF(P24>=DREAD_Guidelines!$B$15,"MEDIUM","LOW")))) | R24: =IF(P24="","",RANK(P24,$P$5:$P$44,0))
A25: 21 | J25: =IF(COUNT(D25:I25)=0,"",SUM(D25:I25)) | P25: =IF(COUNT(K25:O25)=5,SUM(K25:O25),"") | Q25: =IF(P25="","",IF(P25>=DREAD_Guidelines!$B$13,"CRITICAL",IF(P25>=DREAD_Guidelines!$B$14,"HIGH",IF(P25>=DREAD_Guidelines!$B$15,"MEDIUM","LOW")))) | R25: =IF(P25="","",RANK(P25,$P$5:$P$44,0))
A26: 22 | J26: =IF(COUNT(D26:I26)=0,"",SUM(D26:I26)) | P26: =IF(COUNT(K26:O26)=5,SUM(K26:O26),"") | Q26: =IF(P26="","",IF(P26>=DREAD_Guidelines!$B$13,"CRITICAL",IF(P26>=DREAD_Guidelines!$B$14,"HIGH",IF(P26>=DREAD_Guidelines!$B$15,"MEDIUM","LOW")))) | R26: =IF(P26="","",RANK(P26,$P$5:$P$44,0))
... A44: 40 | J44: =IF(COUNT(D44:I44)=0,"",SUM(D44:I44)) | P44: =IF(COUNT(K44:O44)=5,SUM(K44:O44),"") | Q44: =IF(P44="","",IF(P44>=DREAD_Guidelines!$B$13,"CRITICAL",IF(P44>=DREAD_Guidelines!$B$14,"HIGH",IF(P44>=DREAD_Guidelines!$B$15,"MEDIUM","LOW")))) | R44: =IF(P44="","",RANK(P44,$P$5:$P$44,0))

Sheet Pemeriksa_Mandiri
B2: Pemeriksa Mandiri (otomatis; tidak perlu diisi)
B3: Sheet ini memeriksa isian Anda. Perbaiki semua butir yang bertanda PERIKSA di sheet asalnya sampai menjadi OK, lalu simpan. Tanda '-' berarti belum bisa diperiksa karena belum ada ancaman yang diisi. OK bukan jaminan nilai sempurna; ini hanya pemeriksaan bentuk.
B5: No | C5: Pemeriksaan | D5: Hasil | E5: Status | F5: Cara memperbaiki
B6: A. Profil aplikasi
B7: 1 | C7: Bagian A terisi (dari 5 baris) | D7: =COUNTA(Profil_Aplikasi!B5:B9) -> 5 | E7: =IF(D7>=5,"OK","PERIKSA") -> OK | F7: Isi kelima baris bagian A di sheet Profil_Aplikasi.
B8: 2 | C8: Komponen terisi (minimal 4) | D8: =COUNTA(Profil_Aplikasi!B15:B24) -> 10 | E8: =IF(D8>=4,"OK","PERIKSA") -> OK | F8: Tambah komponen pada bagian B (sheet Profil_Aplikasi).
B9: 3 | C9: Aliran data terisi (minimal 4) | D9: =COUNTA(Profil_Aplikasi!B30:B39) -> 10 | E9: =IF(D9>=4,"OK","PERIKSA") -> OK | F9: Tambah aliran data pada bagian C.
B10: 4 | C10: Trust boundary terisi (minimal 2) | D10: =COUNTA(Profil_Aplikasi!B45:B49) -> 5 | E10: =IF(D10>=2,"OK","PERIKSA") -> OK | F10: Isi bagian D: setidaknya batas browser ↔ server dan aplikasi ↔ database.
B11: B. Jumlah dan kelengkapan ancaman
B12: 5 | C12: Jumlah ancaman terisi (minimal 6) | D12: =COUNTA(STRIDE_DREAD_Template!$C$5:$C$44) -> 10 | E12: =IF(D12>=6,"OK","PERIKSA") -> OK | F12: Tambah ancaman baru pada baris kosong di STRIDE_DREAD_Template.
B13: 6 | C13: Ancaman tanpa ID | D13: =SUMPRODUCT(--(STRIDE_DREAD_Template!$C$5:$C$44<>""),--(STRIDE_DREAD_Template!$B$5:$B$44="")) -> 0 | E13: =IF($D$12=0,"-",IF(D13=0,"OK","PERIKSA")) -> OK | F13: Isi kolom B (ID) untuk setiap ancaman, mis. T-01.
B14: 7 | C14: ID kembar | D14: =COUNTA(STRIDE_DREAD_Template!$B$5:$B$44)-SUMPRODUCT((STRIDE_DREAD_Template!$B$5:$B$44<>"")/COUNTIF(STRIDE_DREAD_Template!$B$5:$B$44,STRIDE_DREAD_Template!$B$5:$B$44&"")) -> 0 | E14: =IF($D$12=0,"-",IF(D14=0,"OK","PERIKSA")) -> OK | F14: Setiap ID harus berbeda. Ubah ID yang sama.
B15: 8 | C15: Deskripsi terlalu pendek (< 40 karakter) | D15: =SUMPRODUCT(--(STRIDE_DREAD_Template!$C$5:$C$44<>""),--(LEN(STRIDE_DREAD_Template!$C$5:$C$44)<40)) -> 0 | E15: =IF($D$12=0,"-",IF(D15=0,"OK","PERIKSA")) -> OK | F15: Tulis kalimat lengkap: siapa + melakukan apa + pada bagian mana + akibatnya.
B16: 9 | C16: Ancaman belum punya kategori STRIDE | D16: =SUMPRODUCT(--(STRIDE_DREAD_Template!$C$5:$C$44<>""),--((STRIDE_DREAD_Template!$J$5:$J$44="")+(STRIDE_DREAD_Template!$J$5:$J$44=0)>0)) -> 0 | E16: =IF($D$12=0,"-",IF(D16=0,"OK","PERIKSA")) -> OK | F16: Setiap ancaman perlu minimal satu kolom STRIDE bernilai 1.
B17: 10 | C17: Skor DREAD belum lengkap (5 dimensi) | D17: =SUMPRODUCT(--(STRIDE_DREAD_Template!$C$5:$C$44<>""),--(STRIDE_DREAD_Template!$P$5:$P$44="")) -> 0 | E17: =IF($D$12=0,"-",IF(D17=0,"OK","PERIKSA")) -> OK | F17: Isi kelima skor DREAD (kolom K–O) pada baris itu.
B18: 11 | C18: Baris berskor tetapi tanpa deskripsi | D18: =SUMPRODUCT(--(STRIDE_DREAD_Template!$C$5:$C$44=""),--(STRIDE_DREAD_Template!$P$5:$P$44<>"")) -> 0 | E18: =IF($D$12=0,"-",IF(D18=0,"OK","PERIKSA")) -> OK | F18: Isi kolom Deskripsi atau kosongkan skornya.
B19: C. Kualitas klasifikasi dan skor
B20: 12 | C20: Ancaman dengan 4 atau lebih kategori STRIDE | D20: =COUNTIF(STRIDE_DREAD_Template!$J$5:$J$44,">=4") -> 0 | E20: =IF($D$12=0,"-",IF(D20=0,"OK","PERIKSA")) -> OK | F20: Terlalu longgar. Tandai hanya kategori yang benar-benar terjadi (biasanya 1–2).
B21: 13 | C21: Porsi ancaman bertanda E (Elevation of Privilege) | D21: =IFERROR(SUM(STRIDE_DREAD_Template!$I$5:$I$44)/COUNTA(STRIDE_DREAD_Template!$C$5:$C$44),0) -> 0.2 | E21: =IF($D$12=0,"-",IF(D21<0.5,"OK","PERIKSA")) -> OK | F21: E hanya untuk KENAIKAN HAK AKSES. Baca STRIDE_Guidelines kolom G, lalu ubah E menjadi 0 bila tidak sesuai.
B22: 14 | C22: Jumlah level risiko berbeda yang muncul | D22: =(Ringkasan!C5>0)+(Ringkasan!C6>0)+(Ringkasan!C7>0)+(Ringkasan!C8>0) -> 3 | E22: =IF($D$12=0,"-",IF(D22>=2,"OK","PERIKSA")) -> OK | F22: Skor Anda hampir seragam. Bandingkan antar ancaman dan bedakan skornya sesuai rubrik.
B23: 15 | C23: Rentang total DREAD (tertinggi − terendah) | D23: =IF(COUNT(STRIDE_DREAD_Template!$P$5:$P$44)<2,0,MAX(STRIDE_DREAD_Template!$P$5:$P$44)-MIN(STRIDE_DREAD_Template!$P$5:$P$44)) -> 34 | E23: =IF($D$12=0,"-",IF(D23>=6,"OK","PERIKSA")) -> OK | F23: Rentang sempit: biasanya ada ancaman yang dinilai terlalu tinggi atau terlalu rendah. Tinjau ulang skornya.
B24: 16 | C24: Baris dengan kelima skor DREAD identik (mis. 8-8-8-8-8) | D24: =SUMPRODUCT(--(STRIDE_DREAD_Template!$C$5:$C$44<>""),--(STRIDE_DREAD_Template!$K$5:$K$44=STRIDE_DREAD_Template!$L$5:$L$44),--(STRIDE_DREAD_Template!$L$5:$L$44=STRIDE_DREAD_Template!$M$5:$M$44),--(STRIDE_DREAD_Template!$M$5:$M$44=STRIDE_DREAD_Template!$N$5:$N$44),--(STRIDE_DREAD_Template!$N$5:$N$44=STRIDE_DREAD_Template!$O$5:$O$44),--(STRIDE_DREAD_Template!$K$5:$K$44<>"")) -> 0 | E24: =IF($D$12=0,"-",IF(D24=0,"OK","PERIKSA")) -> OK | F24: Skor dimasukkan tanpa dipikirkan per dimensi. Nilai lagi satu per satu.
B25: D. Penjelasan
B26: 17 | C26: Ancaman tanpa alasan skor (kolom S) | D26: =SUMPRODUCT(--(STRIDE_DREAD_Template!$C$5:$C$44<>""),--(STRIDE_DREAD_Template!$S$5:$S$44="")) -> 0 | E26: =IF($D$12=0,"-",IF(D26=0,"OK","PERIKSA")) -> OK | F26: Tulis satu kalimat per dimensi DREAD.
B27: 18 | C27: Ancaman tanpa bukti (kolom T) | D27: =SUMPRODUCT(--(STRIDE_DREAD_Template!$C$5:$C$44<>""),--(STRIDE_DREAD_Template!$T$5:$T$44="")) -> 0 | E27: =IF($D$12=0,"-",IF(D27=0,"OK","PERIKSA")) -> OK | F27: Tulis dari mana Anda tahu: file + baris, URL halaman, konfigurasi, tangkapan layar.
B28: 19 | C28: Ancaman tanpa saran mitigasi (kolom U) | D28: =SUMPRODUCT(--(STRIDE_DREAD_Template!$C$5:$C$44<>""),--(STRIDE_DREAD_Template!$U$5:$U$44="")) -> 0 | E28: =IF($D$12=0,"-",IF(D28=0,"OK","PERIKSA")) -> OK | F28: Tulis 1–2 tindakan konkret perbaikan.
C30: STATUS KESELURUHAN | D30: =IF(COUNTIF(E6:E28,"PERIKSA")=0,IF(COUNTIF(E6:E28,"OK")=0,"Belum ada isian yang bisa diperiksa","SEMUA OK: siap dikumpulkan (periksa sekali lagi sebelum kirim)"),COUNTIF(E6:E28,"PERIKSA")&" butir masih PERIKSA: perbaiki dulu") -> SEMUA OK: siap dikumpulkan (periksa sekali lagi sebelum kirim)

Sheet Ringkasan
B2: Ringkasan Hasil (otomatis; tidak perlu diisi)
B4: Level Risiko | C4: Jumlah ancaman
B5: CRITICAL | C5: =COUNTIF(STRIDE_DREAD_Template!$Q$5:$Q$44,B5) -> 2
B6: HIGH | C6: =COUNTIF(STRIDE_DREAD_Template!$Q$5:$Q$44,B6) -> 7
B7: MEDIUM | C7: =COUNTIF(STRIDE_DREAD_Template!$Q$5:$Q$44,B7) -> 0
B8: LOW | C8: =COUNTIF(STRIDE_DREAD_Template!$Q$5:$Q$44,B8) -> 1
B9: Total ternilai | C9: =SUM(C5:C8) -> 10
B11: Kategori STRIDE | C11: Jumlah ancaman
B12: Spoofing | C12: =SUM(STRIDE_DREAD_Template!D5:D44) -> 2
B13: Tampering | C13: =SUM(STRIDE_DREAD_Template!E5:E44) -> 6
B14: Repudiation | C14: =SUM(STRIDE_DREAD_Template!F5:F44) -> 0
B15: Information Disclosure | C15: =SUM(STRIDE_DREAD_Template!G5:G44) -> 5
B16: Denial of Service | C16: =SUM(STRIDE_DREAD_Template!H5:H44) -> 2
B17: Elevation of Privilege | C17: =SUM(STRIDE_DREAD_Template!I5:I44) -> 2
B19: Indikator | C19: Nilai
B20: Rata-rata total DREAD | C20: =IFERROR(AVERAGE(STRIDE_DREAD_Template!P5:P44),0) -> 33.8
B21: Skor DREAD tertinggi | C21: =IF(COUNT(STRIDE_DREAD_Template!P5:P44)=0,0,MAX(STRIDE_DREAD_Template!P5:P44)) -> 40
B22: Ancaman prioritas 1 | C22: =IFERROR(INDEX(STRIDE_DREAD_Template!C5:C44,MATCH(1,STRIDE_DREAD_Template!R5:R44,0)),"-") -> Penyerang yang terautentikasi memanipulasi parameter order_id pada endpoint status booking di BookingController tanpa verifikasi kepemilikan akun, sehingga dapat mengubah status pesanan milik pengguna lain secara sepihak.

Sheet STRIDE_Guidelines
A1: Panduan Kategori STRIDE
A3: Kategori | B3: Definisi | C3: Contoh serangan | D3: Aspek keamanan yang dilanggar | E3: Contoh kontrol | F3: Pertanyaan pemicu: tanyakan ini pada tiap komponen / aliran data aplikasi Anda | G3: Pilih kategori ini bila … / jangan pilih bila …
A4: S – Spoofing | B4: Pemalsuan identitas untuk akses ilegal. | C4: Password dicuri, session hijacking | D4: Autentikasi | E4: MFA, rate limit, reCAPTCHA | F4: Bisakah seseorang atau perangkat berpura-pura menjadi pengguna sah (login tanpa verifikasi, password lemah, sesi bisa dicuri)? | G4: Pilih bila pelaku MENYAMAR sebagai pihak lain. Jika pelaku hanya MELIHAT data, itu I, bukan S.
A5: T – Tampering | B5: Perubahan atau manipulasi data. | C5: SQL Injection, modifikasi file | D5: Integritas | E5: Prepared statements, WAF, hash/MAC | F5: Bisakah data, file, atau pengaturan diubah atau dihapus oleh pihak yang tidak berhak (lewat form, parameter URL, file yang bisa ditulis)? | G5: Pilih bila data atau kode DIUBAH atau DIHAPUS. Contoh: SQL Injection yang mengubah isi tabel.
A6: R – Repudiation | B6: Penolakan aksi tanpa bukti. | C6: Log dihapus, aktivitas tidak tercatat | D6: Non-repudiation | E6: Log terverifikasi, tanda tangan digital | F6: Jika seseorang melakukan aksi penting (hapus data, ubah nilai, transfer), adakah catatan yang membuktikan siapa pelakunya? | G6: Pilih bila masalahnya TIDAK ADA BUKTI atau LOG sehingga pelaku bisa menyangkal.
A7: I – Information Disclosure | B7: Kebocoran data sensitif. | C7: Data leak, bucket publik, API tidak aman | D7: Kerahasiaan | E7: Enkripsi, TLS + HSTS, masking | F7: Bisakah pihak tidak berhak MELIHAT data rahasia (password, data pribadi, kode sumber, pesan error rinci, lalu lintas tanpa enkripsi)? | G7: Pilih bila yang bocor adalah INFORMASI (kerahasiaan dilanggar).
A8: D – Denial of Service | B8: Pelumpuhan layanan. | C8: DDoS, resource exhaustion | D8: Ketersediaan | E8: WAF/CDN, rate limiting, autoscaling | F8: Bisakah layanan dibuat lambat atau mati (banjir request, input sangat besar, data penting terhapus, sumber daya habis)? | G8: Pilih bila pengguna sah JADI TIDAK BISA memakai layanan.
A9: E – Elevation of Privilege | B9: Kenaikan hak akses. | C9: Privilege escalation, RCE | D9: Otorisasi | E9: RBAC, least privilege, patching | F9: Bisakah pengguna biasa atau anonim memperoleh hak lebih tinggi (menjadi admin, menjalankan perintah di server, membuka fungsi admin)? | G9: Pilih HANYA bila hak akses NAIK. Membaca data orang lain = I; mengubah data = T. Jangan pilih E hanya karena ancamannya parah.
A11: Cara memakai:
A12: 1. Ambil satu komponen atau aliran data dari sheet Profil_Aplikasi.
A13: 2. Bacakan enam pertanyaan di kolom F satu per satu. Jawaban 'ya, mungkin terjadi' = calon ancaman.
A14: 3. Satu ancaman boleh punya lebih dari satu kategori, tetapi tandai hanya yang benar-benar terjadi. Kebanyakan ancaman cukup 1–2 kategori.
A15: 4. Bila ragu memilih, tanyakan: apa yang dilanggar? Autentikasi → S · Integritas → T · Bukti → R · Kerahasiaan → I · Ketersediaan → D · Otorisasi → E.

Sheet DREAD_Guidelines
A1: Rubrik Skor DREAD (0–10 per dimensi)
A3: Faktor | B3: Pertanyaan penuntun | C3: 0–2 | D3: 3–5 | E3: 6–8 | F3: 9–10
A4: Damage | B4: Seberapa parah kerusakan jika berhasil? | C4: Dampak kecil | D4: Merusak sebagian fungsi | E4: Dampak tinggi | F4: Kritis
A5: Reproducibility | B5: Seberapa mudah serangan diulang? | C5: Sulit diulang | D5: Perlu beberapa langkah | E5: Mudah dengan tools | F5: Sangat mudah
A6: Exploitability | B6: Seberapa mudah dieksploitasi? | C6: Butuh skill tinggi | D6: Butuh autentikasi | E6: Eksploit dari internet | F6: Sangat mudah
A7: Affected Users | B7: Berapa banyak pengguna terdampak? | C7: 1–2 user | D7: 5–10 user | E7: 1 divisi | F7: Semua user
A8: Discoverability | B8: Seberapa mudah celah ditemukan? | C8: Sulit ditemukan | D8: Butuh pengetahuan | E8: Terdeteksi by scan | F8: Sangat mudah ditemukan
A11: Skala Level Risiko (dipakai rumus pada template)
A12: Level | B12: Total DREAD minimum
A13: CRITICAL | B13: 40
A14: HIGH | B14: 30
A15: MEDIUM | B15: 20
A16: LOW | B16: 0
A18: Batas level ditetapkan dosen; mahasiswa tidak perlu mengubahnya. Total DREAD = jumlah lima dimensi (maks 50).
A20: Panduan praktis untuk pemula
A21: Faktor | B21: Tanyakan pada diri sendiri | C21: Contoh nilai tinggi (9–10) | D21: Contoh nilai rendah (0–2)
A22: Damage | B22: Jika serangan berhasil, apa yang hilang atau rusak? Bisakah dipulihkan? | C22: Seluruh data hilang permanen tanpa cadangan. | D22: Hanya tampilan berubah sementara.
A23: Reproducibility | B23: Apakah serangan berhasil setiap kali dicoba, atau perlu keberuntungan dan kondisi khusus? | C23: Satu URL atau satu request, selalu berhasil. | D23: Hanya berhasil pada kondisi yang sangat langka.
A24: Exploitability | B24: Apa yang dibutuhkan penyerang: keahlian, alat, akses awal (harus login? satu jaringan?) | C24: Siapa pun dengan browser, tanpa login. | D24: Perlu akses admin dan keahlian tinggi.
A25: Affected Users | B25: Berapa banyak pengguna atau data yang terdampak? | C25: Semua pengguna sistem. | D25: Satu pengguna saja.
A26: Discoverability | B26: Seberapa mudah penyerang menemukan celahnya? | C26: Terlihat langsung di halaman, URL, atau kode yang publik. | D26: Harus membaca kode internal atau menebak.
A28: Tips: (1) beri skor satu dimensi pada satu waktu; (2) tulis asumsi Anda di kolom Catatan; (3) bandingkan antar ancaman: ancaman yang menurut Anda paling parah harus mendapat total tertinggi; (4) skor bukan rasa takut: ancaman yang terdengar seram tetapi sulit dilakukan skornya tidak semuanya tinggi.

Sheet Glosarium_Istilah
A1: Glosarium Istilah Teknis
A2: Istilah yang dipakai pada berkas ini, dikelompokkan menurut kategori. Kolom terakhir hanya memberi contoh dari aplikasi contoh dosen (mon_server), bukan dari aplikasi Anda.
A3: No | B3: Istilah | C3: Kategori | D3: Penjelasan | E3: Contoh pada aplikasi contoh dosen (mon_server)
A4: 1 | B4: Threat modelling (pemodelan ancaman) | C4: Konsep | D4: Proses sistematis menemukan, menilai, dan memprioritaskan ancaman terhadap sebuah sistem sebelum ancaman itu dieksploitasi. | E4: Seluruh file ini: 15 ancaman terhadap aplikasi mon_server.
A5: 2 | B5: Aset | C5: Konsep | D5: Sesuatu yang bernilai dan perlu dilindungi: data, layanan, atau kredensial. | E5: Data sensor di tb_monitoring, ketersediaan dashboard, password WiFi.
A6: 3 | B6: Aktor ancaman (threat actor) | C6: Konsep | D6: Pihak yang dapat menyerang sistem, baik orang dalam maupun luar. | E6: Penyerang di jaringan WiFi yang sama; pengunjung anonim.
A7: 4 | B7: Vektor serangan | C7: Konsep | D7: Jalur atau cara yang dipakai penyerang untuk mencapai sasaran. | E7: URL input.php?cahaya=…, halaman delete_data.php.
A8: 5 | B8: Kerentanan (vulnerability) | C8: Konsep | D8: Kelemahan pada desain, kode, atau konfigurasi yang dapat dimanfaatkan penyerang. | E8: Tidak ada autentikasi pada input.php.
A9: 6 | B9: Ancaman vs risiko | C9: Konsep | D9: Ancaman adalah kejadian merugikan yang mungkin terjadi. Risiko adalah gabungan kemungkinan terjadinya dan besar dampaknya. | E9: DREAD dipakai untuk mengubah daftar ancaman menjadi tingkat risiko.
A10: 7 | B10: Mitigasi / kontrol | C10: Konsep | D10: Tindakan untuk mengurangi kemungkinan atau dampak suatu ancaman. | E10: Bagian 'Mitigasi' pada kolom Catatan tiap baris.
A11: 8 | B11: Sisa risiko (residual risk) | C11: Konsep | D11: Risiko yang masih tersisa setelah mitigasi diterapkan. | E11: T-14: real_escape_string sudah ada, tetapi masih tersisa risiko bila kode berubah.
A12: 9 | B12: Analisis statis | C12: Konsep | D12: Menilai keamanan dengan membaca kode tanpa menjalankan atau menyerang sistem. | E12: Dasar seluruh temuan pada file ini.
